Workbook

Sheet main
A1: Rank | B1: Player ID | C1: Player | D1: Last Name | E1: First | F1: Clean Name | G1: Team | H1: Position | I1: ADP | J1: Min Pick | K1: Max Pick | L1: Bye Week | M1: Bye Week 5 | N1: Bye Week 6 | O1: Bye Week 7 | P1: Bye Week 8 | Q1: Bye Week 9 | R1: Bye Week 10 | S1: Bye Week 11 | T1: Bye Week 12 | U1: Bye Week 14 | V1: Is QB | W1: Is RB | X1: Is WR | Y1: Is TE | Z1: Is Flex | AA1: Is Superflex | AB1: PFF PPR | AC1: numberFire PPR | AD1: Rotoballer PPR | AE1: Athletic PPR | AF1: Athletic Half | AG1: Athletic STD | AH1: Week 11 Actual
A2: 1 | B2: 18775 | C2: Chase, Ja'Marr | D2: {=_xlfn.TEXTSPLIT(C2, ", ")} -> Chase | E2: Ja'Marr | F2: =_xlfn.REGEXREPLACE(E2 & " " & D2, "\.", "") -> Ja'Marr Chase | G2: CIN | H2: WR | I2: 1.12 | J2: 1 | K2: 4 | L2: =VLOOKUP(G2,byes!$A:$B,2,FALSE) -> 10 | M2: =IF(L2=5,1,0) -> 0 | N2: =IF(L2=6,1,0) -> 0 | O2: =IF(L2=7,1,0) -> 0 | P2: =IF(L2=8,1,0) -> 0 | Q2: =IF(L2=9,1,0) -> 0 | R2: =IF(L2=10,1,0) -> 1 | S2: =IF(L2=11,1,0) -> 0 | T2: =IF(L2=12,1,0) -> 0 | U2: =IF(L2=14,1,0) -> 0 | V2: =IF(H2="QB", 1, 0) -> 0 | W2: =IF(H2="RB",1,0) -> 0 | X2: =IF(H2="WR",1,0) -> 1 | Y2: =IF(H2="TE",1,0) -> 0 | Z2: =IF(OR(H2="RB",H2="WR",H2="TE"),1,0) -> 1 | AA2: 1 | AB2: =VLOOKUP(F2,[1]pff_ppr_projections!$B:$D,3,FALSE) -> 333.4 | AC2: =VLOOKUP(F2,[2]numberFire_ppr_projections!$A:$B,2,FALSE) -> 390.8 | AD2: =VLOOKUP(F2,[3]rotoballer_ppr_projections!$B:$G,6,FALSE) -> 355 | AE2: =VLOOKUP(F2,[4]ppr!$B:$E,4,FALSE) -> 314.52609 | AF2: =VLOOKUP(F2,[4]half_ppr!$B:$E,4,FALSE) -> 260.96238 | AG2: =VLOOKUP(F2,[4]std!$B:$E,4,FALSE) -> 207.39867 | AH2: =IFERROR(VLOOKUP(F2,[5]actual_week11_ppr_stats!$A:$B,2,FALSE),0) -> 195.7
A3: 2 | B3: 20271 | C3: Robinson, Bijan | D3: {=_xlfn.TEXTSPLIT(C3, ", ")} -> Robinson | E3: Bijan | F3: =_xlfn.REGEXREPLACE(E3 & " " & D3, "\.", "") -> Bijan Robinson | G3: ATL | H3: RB | I3: 2.44 | J3: 1 | K3: 6 | L3: =VLOOKUP(G3,byes!$A:$B,2,FALSE) -> 5 | M3: =IF(L3=5,1,0) -> 1 | N3: =IF(L3=6,1,0) -> 0 | O3: =IF(L3=7,1,0) -> 0 | P3: =IF(L3=8,1,0) -> 0 | Q3: =IF(L3=9,1,0) -> 0 | R3: =IF(L3=10,1,0) -> 0 | S3: =IF(L3=11,1,0) -> 0 | T3: =IF(L3=12,1,0) -> 0 | U3: =IF(L3=14,1,0) -> 0 | V3: =IF(H3="QB", 1, 0) -> 0 | W3: =IF(H3="RB",1,0) -> 1 | X3: =IF(H3="WR",1,0) -> 0 | Y3: =IF(H3="TE",1,0) -> 0 | Z3: =IF(OR(H3="RB",H3="WR",H3="TE"),1,0) -> 1 | AA3: 1 | AB3: =VLOOKUP(F3,[1]pff_ppr_projections!$B:$D,3,FALSE) -> 299.4 | AC3: =VLOOKUP(F3,[2]numberFire_ppr_projections!$A:$B,2,FALSE) -> 321.1 | AD3: =VLOOKUP(F3,[3]rotoballer_ppr_projections!$B:$G,6,FALSE) -> 329 | AE3: =VLOOKUP(F3,[4]ppr!$B:$E,4,FALSE) -> 295.88629 | AF3: =VLOOKUP(F3,[4]half_ppr!$B:$E,4,FALSE) -> 274.99156 | AG3: =VLOOKUP(F3,[4]std!$B:$E,4,FALSE) -> 254.09683 | AH3: =IFERROR(VLOOKUP(F3,[5]actual_week11_ppr_stats!$A:$B,2,FALSE),0) -> 211.9
A4: 3 | B4: 20272 | C4: Gibbs, Jahmyr | D4: {=_xlfn.TEXTSPLIT(C4, ", ")} -> Gibbs | E4: Jahmyr | F4: =_xlfn.REGEXREPLACE(E4 & " " & D4, "\.", "") -> Jahmyr Gibbs | G4: DET | H4: RB | I4: 3.44 | J4: 1 | K4: 6 | L4: =VLOOKUP(G4,byes!$A:$B,2,FALSE) -> 8 | M4: =IF(L4=5,1,0) -> 0 | N4: =IF(L4=6,1,0) -> 0 | O4: =IF(L4=7,1,0) -> 0 | P4: =IF(L4=8,1,0) -> 1 | Q4: =IF(L4=9,1,0) -> 0 | R4: =IF(L4=10,1,0) -> 0 | S4: =IF(L4=11,1,0) -> 0 | T4: =IF(L4=12,1,0) -> 0 | U4: =IF(L4=14,1,0) -> 0 | V4: =IF(H4="QB", 1, 0) -> 0 | W4: =IF(H4="RB",1,0) -> 1 | X4: =IF(H4="WR",1,0) -> 0 | Y4: =IF(H4="TE",1,0) -> 0 | Z4: =IF(OR(H4="RB",H4="WR",H4="TE"),1,0) -> 1 | AA4: 1 | AB4: =VLOOKUP(F4,[1]pff_ppr_projections!$B:$D,3,FALSE) -> 295.1 | AC4: =VLOOKUP(F4,[2]numberFire_ppr_projections!$A:$B,2,FALSE) -> 334.6 | AD4: =VLOOKUP(F4,[3]rotoballer_ppr_projections!$B:$G,6,FALSE) -> 324 | AE4: =VLOOKUP(F4,[4]ppr!$B:$E,4,FALSE) -> 310.20755 | AF4: =VLOOKUP(F4,[4]half_ppr!$B:$E,4,FALSE) -> 283.12123 | AG4: =VLOOKUP(F4,[4]std!$B:$E,4,FALSE) -> 256.0349 | AH4: =IFERROR(VLOOKUP(F4,[5]actual_week11_ppr_stats!$A:$B,2,FALSE),0) -> 203.6
A5: 4 | B5: 17965 | C5: Lamb, CeeDee | D5: {=_xlfn.TEXTSPLIT(C5, ", ")} -> Lamb | E5: CeeDee | F5: =_xlfn.REGEXREPLACE(E5 & " " & D5, "\.", "") -> CeeDee Lamb | G5: DAL | H5: WR | I5: 3.83 | J5: 2 | K5: 7 | L5: =VLOOKUP(G5,byes!$A:$B,2,FALSE) -> 10 | M5: =IF(L5=5,1,0) -> 0 | N5: =IF(L5=6,1,0) -> 0 | O5: =IF(L5=7,1,0) -> 0 | P5: =IF(L5=8,1,0) -> 0 | Q5: =IF(L5=9,1,0) -> 0 | R5: =IF(L5=10,1,0) -> 1 | S5: =IF(L5=11,1,0) -> 0 | T5: =IF(L5=12,1,0) -> 0 | U5: =IF(L5=14,1,0) -> 0 | V5: =IF(H5="QB", 1, 0) -> 0 | W5: =IF(H5="RB",1,0) -> 0 | X5: =IF(H5="WR",1,0) -> 1 | Y5: =IF(H5="TE",1,0) -> 0 | Z5: =IF(OR(H5="RB",H5="WR",H5="TE"),1,0) -> 1 | AA5: =IF(OR(H5="RB",H5="WR",H5="TE", H5="QB"),1,0) -> 1 | AB5: =VLOOKUP(F5,[1]pff_ppr_projections!$B:$D,3,FALSE) -> 274.6 | AC5: =VLOOKUP(F5,[2]numberFire_ppr_projections!$A:$B,2,FALSE) -> 322.7 | AD5: =VLOOKUP(F5,[3]rotoballer_ppr_projections!$B:$G,6,FALSE) -> 301 | AE5: =VLOOKUP(F5,[4]ppr!$B:$E,4,FALSE) -> 302.70262 | AF5: =VLOOKUP(F5,[4]half_ppr!$B:$E,4,FALSE) -> 248.09918 | AG5: =VLOOKUP(F5,[4]std!$B:$E,4,FALSE) -> 193.49574 | AH5: =IFERROR(VLOOKUP(F5,[5]actual_week11_ppr_stats!$A:$B,2,FALSE),0) -> 107.9
A6: 5 | B6: 16062 | C6: Barkley, Saquon | D6: {=_xlfn.TEXTSPLIT(C6, ", ")} -> Barkley | E6: Saquon | F6: =_xlfn.REGEXREPLACE(E6 & " " & D6, "\.", "") -> Saquon Barkley | G6: PHI | H6: RB | I6: 5.11 | J6: 2 | K6: 8 | L6: =VLOOKUP(G6,byes!$A:$B,2,FALSE) -> 9 | M6: =IF(L6=5,1,0) -> 0 | N6: =IF(L6=6,1,0) -> 0 | O6: =IF(L6=7,1,0) -> 0 | P6: =IF(L6=8,1,0) -> 0 | Q6: =IF(L6=9,1,0) -> 1 | R6: =IF(L6=10,1,0) -> 0 | S6: =IF(L6=11,1,0) -> 0 | T6: =IF(L6=12,1,0) -> 0 | U6: =IF(L6=14,1,0) -> 0 | V6: =IF(H6="QB", 1, 0) -> 0 | W6: =IF(H6="RB",1,0) -> 1 | X6: =IF(H6="WR",1,0) -> 0 | Y6: =IF(H6="TE",1,0) -> 0 | Z6: =IF(OR(H6="RB",H6="WR",H6="TE"),1,0) -> 1 | AA6: 1 | AB6: =VLOOKUP(F6,[1]pff_ppr_projections!$B:$D,3,FALSE) -> 285.5 | AC6: =VLOOKUP(F6,[2]numberFire_ppr_projections!$A:$B,2,FALSE) -> 327.2 | AD6: =VLOOKUP(F6,[3]rotoballer_ppr_projections!$B:$G,6,FALSE) -> 311 | AE6: =VLOOKUP(F6,[4]ppr!$B:$E,4,FALSE) -> 283.51124 | AF6: =VLOOKUP(F6,[4]half_ppr!$B:$E,4,FALSE) -> 265.40973 | AG6: =VLOOKUP(F6,[4]std!$B:$E,4,FALSE) -> 247.30823 | AH6: =IFERROR(VLOOKUP(F6,[5]actual_week11_ppr_stats!$A:$B,2,FALSE),0) -> 150.9
A7: 6 | B7: 17972 | C7: Jefferson, Justin | D7: {=_xlfn.TEXTSPLIT(C7, ", ")} -> Jefferson | E7: Justin | F7: =_xlfn.REGEXREPLACE(E7 & " " & D7, "\.", "") -> Justin Jefferson | G7: MIN | H7: WR | I7: 5.69 | J7: 2 | K7: 8 | L7: =VLOOKUP(G7,byes!$A:$B,2,FALSE) -> 6 | M7: =IF(L7=5,1,0) -> 0 | N7: =IF(L7=6,1,0) -> 1 | O7: =IF(L7=7,1,0) -> 0 | P7: =IF(L7=8,1,0) -> 0 | Q7: =IF(L7=9,1,0) -> 0 | R7: =IF(L7=10,1,0) -> 0 | S7: =IF(L7=11,1,0) -> 0 | T7: =IF(L7=12,1,0) -> 0 | U7: =IF(L7=14,1,0) -> 0 | V7: =IF(H7="QB", 1, 0) -> 0 | W7: =IF(H7="RB",1,0) -> 0 | X7: =IF(H7="WR",1,0) -> 1 | Y7: =IF(H7="TE",1,0) -> 0 | Z7: =IF(OR(H7="RB",H7="WR",H7="TE"),1,0) -> 1 | AA7: 1 | AB7: =VLOOKUP(F7,[1]pff_ppr_projections!$B:$D,3,FALSE) -> 291.2 | AC7: =VLOOKUP(F7,[2]numberFire_ppr_projections!$A:$B,2,FALSE) -> 344.7 | AD7: =VLOOKUP(F7,[3]rotoballer_ppr_projections!$B:$G,6,FALSE) -> 295 | AE7: =VLOOKUP(F7,[4]ppr!$B:$E,4,FALSE) -> 289.815 | AF7: =VLOOKUP(F7,[4]half_ppr!$B:$E,4,FALSE) -> 240.6831 | AG7: =VLOOKUP(F7,[4]std!$B:$E,4,FALSE) -> 191.5512 | AH7: =IFERROR(VLOOKUP(F7,[5]actual_week11_ppr_stats!$A:$B,2,FALSE),0) -> 143.1
A8: 7 | B8: 15222 | C8: McCaffrey, Christian | D8: {=_xlfn.TEXTSPLIT(C8, ", ")} -> McCaffrey | E8: Christian | F8: =_xlfn.REGEXREPLACE(E8 & " " & D8, "\.", "") -> Christian McCaffrey | G8: SF | H8: RB | I8: 7.5 | J8: 3 | K8: 14 | L8: =VLOOKUP(G8,byes!$A:$B,2,FALSE) -> 14 | M8: =IF(L8=5,1,0) -> 0 | N8: =IF(L8=6,1,0) -> 0 | O8: =IF(L8=7,1,0) -> 0 | P8: =IF(L8=8,1,0) -> 0 | Q8: =IF(L8=9,1,0) -> 0 | R8: =IF(L8=10,1,0) -> 0 | S8: =IF(L8=11,1,0) -> 0 | T8: =IF(L8=12,1,0) -> 0 | U8: =IF(L8=14,1,0) -> 1 | V8: =IF(H8="QB", 1, 0) -> 0 | W8: =IF(H8="RB",1,0) -> 1 | X8: =IF(H8="WR",1,0) -> 0 | Y8: =IF(H8="TE",1,0) -> 0 | Z8: =IF(OR(H8="RB",H8="WR",H8="TE"),1,0) -> 1 | AA8: 1 | AB8: =VLOOKUP(F8,[1]pff_ppr_projections!$B:$D,3,FALSE) -> 277.2 | AC8: =VLOOKUP(F8,[2]numberFire_ppr_projections!$A:$B,2,FALSE) -> 336.8 | AD8: =VLOOKUP(F8,[3]rotoballer_ppr_projections!$B:$G,6,FALSE) -> 288 | AE8: =VLOOKUP(F8,[4]ppr!$B:$E,4,FALSE) -> 340.87175 | AF8: =VLOOKUP(F8,[4]half_ppr!$B:$E,4,FALSE) -> 311.12829 | AG8: =VLOOKUP(F8,[4]std!$B:$E,4,FALSE) -> 281.38483 | AH8: =IFERROR(VLOOKUP(F8,[5]actual_week11_ppr_stats!$A:$B,2,FALSE),0) -> 283.9
A9: 8 | B9: 21122 | C9: Nabers, Malik | D9: {=_xlfn.TEXTSPLIT(C9, ", ")} -> Nabers | E9: Malik | F9: =_xlfn.REGEXREPLACE(E9 & " " & D9, "\.", "") -> Malik Nabers | G9: NYG | H9: WR | I9: 8.78 | J9: 6 | K9: 12 | L9: =VLOOKUP(G9,byes!$A:$B,2,FALSE) -> 14 | M9: =IF(L9=5,1,0) -> 0 | N9: =IF(L9=6,1,0) -> 0 | O9: =IF(L9=7,1,0) -> 0 | P9: =IF(L9=8,1,0) -> 0 | Q9: =IF(L9=9,1,0) -> 0 | R9: =IF(L9=10,1,0) -> 0 | S9: =IF(L9=11,1,0) -> 0 | T9: =IF(L9=12,1,0) -> 0 | U9: =IF(L9=14,1,0) -> 1 | V9: =IF(H9="QB", 1, 0) -> 0 | W9: =IF(H9="RB",1,0) -> 0 | X9: =IF(H9="WR",1,0) -> 1 | Y9: =IF(H9="TE",1,0) -> 0 | Z9: =IF(OR(H9="RB",H9="WR",H9="TE"),1,0) -> 1 | AA9: =IF(OR(H9="RB",H9="WR",H9="TE", H9="QB"),1,0) -> 1 | AB9: =VLOOKUP(F9,[1]pff_ppr_projections!$B:$D,3,FALSE) -> 266 | AC9: =VLOOKUP(F9,[2]numberFire_ppr_projections!$A:$B,2,FALSE) -> 281.5 | AD9: =AVERAGE(AB9,AC9,AE9) -> 273.84658 | AE9: =VLOOKUP(F9,[4]ppr!$B:$E,4,FALSE) -> 274.03975 | AF9: =VLOOKUP(F9,[4]half_ppr!$B:$E,4,FALSE) -> 221.96074 | AG9: =VLOOKUP(F9,[4]std!$B:$E,4,FALSE) -> 169.88173 | AH9: =IFERROR(VLOOKUP(F9,[5]actual_week11_ppr_stats!$A:$B,2,FALSE),0) -> 57.1
A10: 9 | B10: 18827 | C10: St. Brown, Amon-Ra | D10: {=_xlfn.TEXTSPLIT(C10, ", ")} -> St. Brown | E10: Amon-Ra | F10: =_xlfn.REGEXREPLACE(E10 & " " & D10, "\.", "") -> Amon-Ra St Brown | G10: DET | H10: WR | I10: 10.17 | J10: 6 | K10: 16 | L10: =VLOOKUP(G10,byes!$A:$B,2,FALSE) -> 8 | M10: =IF(L10=5,1,0) -> 0 | N10: =IF(L10=6,1,0) -> 0 | O10: =IF(L10=7,1,0) -> 0 | P10: =IF(L10=8,1,0) -> 1 | Q10: =IF(L10=9,1,0) -> 0 | R10: =IF(L10=10,1,0) -> 0 | S10: =IF(L10=11,1,0) -> 0 | T10: =IF(L10=12,1,0) -> 0 | U10: =IF(L10=14,1,0) -> 0 | V10: =IF(H10="QB", 1, 0) -> 0 | W10: =IF(H10="RB",1,0) -> 0 | X10: =IF(H10="WR",1,0) -> 1 | Y10: =IF(H10="TE",1,0) -> 0 | Z10: =IF(OR(H10="RB",H10="WR",H10="TE"),1,0) -> 1 | AA10: 1 | AB10: =VLOOKUP(F10,[1]pff_ppr_projections!$B:$D,3,FALSE) -> 270 | AC10: =VLOOKUP(F10,[2]numberFire_ppr_projections!$A:$B,2,FALSE) -> 315.9 | AD10: =VLOOKUP(F10,[3]rotoballer_ppr_projections!$B:$G,6,FALSE) -> 288 | AE10: =VLOOKUP(F10,[4]ppr!$B:$E,4,FALSE) -> 287.26189 | AF10: =VLOOKUP(F10,[4]half_ppr!$B:$E,4,FALSE) -> 233.79024 | AG10: =VLOOKUP(F10,[4]std!$B:$E,4,FALSE) -> 180.31859 | AH10: =IFERROR(VLOOKUP(F10,[5]actual_week11_ppr_stats!$A:$B,2,FALSE),0) -> 188.4
A11: 10 | B11: 21131 | C11: Thomas Jr., Brian | D11: {=_xlfn.TEXTSPLIT(C11, ", ")} -> Thomas Jr. | E11: Brian | F11: =_xlfn.REGEXREPLACE(E11 & " " & D11, "\.", "") -> Brian Thomas Jr | G11: JAX | H11: WR | I11: 10.51 | J11: 7 | K11: 17 | L11: =VLOOKUP(G11,byes!$A:$B,2,FALSE) -> 8 | M11: =IF(L11=5,1,0) -> 0 | N11: =IF(L11=6,1,0) -> 0 | O11: =IF(L11=7,1,0) -> 0 | P11: =IF(L11=8,1,0) -> 1 | Q11: =IF(L11=9,1,0) -> 0 | R11: =IF(L11=10,1,0) -> 0 | S11: =IF(L11=11,1,0) -> 0 | T11: =IF(L11=12,1,0) -> 0 | U11: =IF(L11=14,1,0) -> 0 | V11: =IF(H11="QB", 1, 0) -> 0 | W11: =IF(H11="RB",1,0) -> 0 | X11: =IF(H11="WR",1,0) -> 1 | Y11: =IF(H11="TE",1,0) -> 0 | Z11: =IF(OR(H11="RB",H11="WR",H11="TE"),1,0) -> 1 | AA11: 1 | AB11: =VLOOKUP(F11,[1]pff_ppr_projections!$B:$D,3,FALSE) -> 287.1 | AC11: =VLOOKUP(F11,[2]numberFire_ppr_projections!$A:$B,2,FALSE) -> 286.7 | AD11: =VLOOKUP(F11,[3]rotoballer_ppr_projections!$B:$G,6,FALSE) -> 269 | AE11: =VLOOKUP(F11,[4]ppr!$B:$E,4,FALSE) -> 271.20468 | AF11: =VLOOKUP(F11,[4]half_ppr!$B:$E,4,FALSE) -> 224.49357 | AG11: =VLOOKUP(F11,[4]std!$B:$E,4,FALSE) -> 177.78247 | AH11: =IFERROR(VLOOKUP(F11,[5]actual_week11_ppr_stats!$A:$B,2,FALSE),0) -> 85.6
A12: 11 | B12: 18836 | C12: Collins, Nico | D12: {=_xlfn.TEXTSPLIT(C12, ", ")} -> Collins | E12: Nico | F12: =_xlfn.REGEXREPLACE(E12 & " " & D12, "\.", "") -> Nico Collins | G12: HOU | H12: WR | I12: 11.11 | J12: 7 | K12: 16 | L12: =VLOOKUP(G12,byes!$A:$B,2,FALSE) -> 6 | M12: =IF(L12=5,1,0) -> 0 | N12: =IF(L12=6,1,0) -> 1 | O12: =IF(L12=7,1,0) -> 0 | P12: =IF(L12=8,1,0) -> 0 | Q12: =IF(L12=9,1,0) -> 0 | R12: =IF(L12=10,1,0) -> 0 | S12: =IF(L12=11,1,0) -> 0 | T12: =IF(L12=12,1,0) -> 0 | U12: =IF(L12=14,1,0) -> 0 | V12: =IF(H12="QB", 1, 0) -> 0 | W12: =IF(H12="RB",1,0) -> 0 | X12: =IF(H12="WR",1,0) -> 1 | Y12: =IF(H12="TE",1,0) -> 0 | Z12: =IF(OR(H12="RB",H12="WR",H12="TE"),1,0) -> 1 | AA12: 1 | AB12: =VLOOKUP(F12,[1]pff_ppr_projections!$B:$D,3,FALSE) -> 277.3 | AC12: =VLOOKUP(F12,[2]numberFire_ppr_projections!$A:$B,2,FALSE) -> 285.8 | AD12: =VLOOKUP(F12,[3]rotoballer_ppr_projections!$B:$G,6,FALSE) -> 281 | AE12: =VLOOKUP(F12,[4]ppr!$B:$E,4,FALSE) -> 263.12238 | AF12: =VLOOKUP(F12,[4]half_ppr!$B:$E,4,FALSE) -> 217.55217 | AG12: =VLOOKUP(F12,[4]std!$B:$E,4,FALSE) -> 171.98196 | AH12: =IFERROR(VLOOKUP(F12,[5]actual_week11_ppr_stats!$A:$B,2,FALSE),0) -> 146.5
A13: 12 | B13: 22055 | C13: Jeanty, Ashton | D13: {=_xlfn.TEXTSPLIT(C13, ", ")} -> Jeanty | E13: Ashton | F13: =_xlfn.REGEXREPLACE(E13 & " " & D13, "\.", "") -> Ashton Jeanty | G13: LV | H13: RB | I13: 11.5 | J13: 5 | K13: 18 | L13: =VLOOKUP(G13,byes!$A:$B,2,FALSE) -> 8 | M13: =IF(L13=5,1,0) -> 0 | N13: =IF(L13=6,1,0) -> 0 | O13: =IF(L13=7,1,0) -> 0 | P13: =IF(L13=8,1,0) -> 1 | Q13: =IF(L13=9,1,0) -> 0 | R13: =IF(L13=10,1,0) -> 0 | S13: =IF(L13=11,1,0) -> 0 | T13: =IF(L13=12,1,0) -> 0 | U13: =IF(L13=14,1,0) -> 0 | V13: =IF(H13="QB", 1, 0) -> 0 | W13: =IF(H13="RB",1,0) -> 1 | X13: =IF(H13="WR",1,0) -> 0 | Y13: =IF(H13="TE",1,0) -> 0 | Z13: =IF(OR(H13="RB",H13="WR",H13="TE"),1,0) -> 1 | AA13: =IF(OR(H13="RB",H13="WR",H13="TE", H13="QB"),1,0) -> 1 | AB13: =VLOOKUP(F13,[1]pff_ppr_projections!$B:$D,3,FALSE) -> 290.3 | AC13: =VLOOKUP(F13,[2]numberFire_ppr_projections!$A:$B,2,FALSE) -> 219.9 | AD13: =VLOOKUP(F13,[3]rotoballer_ppr_projections!$B:$G,6,FALSE) -> 252 | AE13: =VLOOKUP(F13,[4]ppr!$B:$E,4,FALSE) -> 243.89725 | AF13: =VLOOKUP(F13,[4]half_ppr!$B:$E,4,FALSE) -> 227.18267 | AG13: =VLOOKUP(F13,[4]std!$B:$E,4,FALSE) -> 210.46809 | AH13: =IFERROR(VLOOKUP(F13,[5]actual_week11_ppr_stats!$A:$B,2,FALSE),0) -> 142.7
A14: 13 | B14: 19433 | C14: London, Drake | D14: {=_xlfn.TEXTSPLIT(C14, ", ")} -> London | E14: Drake | F14: =_xlfn.REGEXREPLACE(E14 & " " & D14, "\.", "") -> Drake London | G14: ATL | H14: WR | I14: 13.34 | J14: 6 | K14: 20 | L14: =VLOOKUP(G14,byes!$A:$B,2,FALSE) -> 5 | M14: =IF(L14=5,1,0) -> 1 | N14: =IF(L14=6,1,0) -> 0 | O14: =IF(L14=7,1,0) -> 0 | P14: =IF(L14=8,1,0) -> 0 | Q14: =IF(L14=9,1,0) -> 0 | R14: =IF(L14=10,1,0) -> 0 | S14: =IF(L14=11,1,0) -> 0 | T14: =IF(L14=12,1,0) -> 0 | U14: =IF(L14=14,1,0) -> 0 | V14: =IF(H14="QB", 1, 0) -> 0 | W14: =IF(H14="RB",1,0) -> 0 | X14: =IF(H14="WR",1,0) -> 1 | Y14: =IF(H14="TE",1,0) -> 0 | Z14: =IF(OR(H14="RB",H14="WR",H14="TE"),1,0) -> 1 | AA14: 1 | AB14: =VLOOKUP(F14,[1]pff_ppr_projections!$B:$D,3,FALSE) -> 259.4 | AC14: =VLOOKUP(F14,[2]numberFire_ppr_projections!$A:$B,2,FALSE) -> 282.1 | AD14: =VLOOKUP(F14,[3]rotoballer_ppr_projections!$B:$G,6,FALSE) -> 271 | AE14: =VLOOKUP(F14,[4]ppr!$B:$E,4,FALSE) -> 273.56591 | AF14: =VLOOKUP(F14,[4]half_ppr!$B:$E,4,FALSE) -> 224.27476 | AG14: =VLOOKUP(F14,[4]std!$B:$E,4,FALSE) -> 174.9836 | AH14: =IFERROR(VLOOKUP(F14,[5]actual_week11_ppr_stats!$A:$B,2,FALSE),0) -> 177
A15: 14 | B15: 15055 | C15: Henry, Derrick | D15: {=_xlfn.TEXTSPLIT(C15, ", ")} -> Henry | E15: Derrick | F15: =_xlfn.REGEXREPLACE(E15 & " " & D15, "\.", "") -> Derrick Henry | G15: BAL | H15: RB | I15: 13.47 | J15: 7 | K15: 19 | L15: =VLOOKUP(G15,byes!$A:$B,2,FALSE) -> 7 | M15: =IF(L15=5,1,0) -> 0 | N15: =IF(L15=6,1,0) -> 0 | O15: =IF(L15=7,1,0) -> 1 | P15: =IF(L15=8,1,0) -> 0 | Q15: =IF(L15=9,1,0) -> 0 | R15: =IF(L15=10,1,0) -> 0 | S15: =IF(L15=11,1,0) -> 0 | T15: =IF(L15=12,1,0) -> 0 | U15: =IF(L15=14,1,0) -> 0 | V15: =IF(H15="QB", 1, 0) -> 0 | W15: =IF(H15="RB",1,0) -> 1 | X15: =IF(H15="WR",1,0) -> 0 | Y15: =IF(H15="TE",1,0) -> 0 | Z15: =IF(OR(H15="RB",H15="WR",H15="TE"),1,0) -> 1 | AA15: 1 | AB15: =VLOOKUP(F15,[1]pff_ppr_projections!$B:$D,3,FALSE) -> 252.5 | AC15: =VLOOKUP(F15,[2]numberFire_ppr_projections!$A:$B,2,FALSE) -> 223.5 | AD15: =VLOOKUP(F15,[3]rotoballer_ppr_projections!$B:$G,6,FALSE) -> 274 | AE15: =VLOOKUP(F15,[4]ppr!$B:$E,4,FALSE) -> 273.22939 | AF15: =VLOOKUP(F15,[4]half_ppr!$B:$E,4,FALSE) -> 264.0538 | AG15: =VLOOKUP(F15,[4]std!$B:$E,4,FALSE) -> 254.87821 | AH15: =IFERROR(VLOOKUP(F15,[5]actual_week11_ppr_stats!$A:$B,2,FALSE),0) -> 141.1
A16: 15 | B16: 20336 | C16: Nacua, Puka | D16: {=_xlfn.TEXTSPLIT(C16, ", ")} -> Nacua | E16: Puka | F16: =_xlfn.REGEXREPLACE(E16 & " " & D16, "\.", "") -> Puka Nacua | G16: LA | H16: WR | I16: 14.41 | J16: 8 | K16: 22 | L16: =VLOOKUP(G16,byes!$A:$B,2,FALSE) -> 8 | M16: =IF(L16=5,1,0) -> 0 | N16: =IF(L16=6,1,0) -> 0 | O16: =IF(L16=7,1,0) -> 0 | P16: =IF(L16=8,1,0) -> 1 | Q16: =IF(L16=9,1,0) -> 0 | R16: =IF(L16=10,1,0) -> 0 | S16: =IF(L16=11,1,0) -> 0 | T16: =IF(L16=12,1,0) -> 0 | U16: =IF(L16=14,1,0) -> 0 | V16: =IF(H16="QB", 1, 0) -> 0 | W16: =IF(H16="RB",1,0) -> 0 | X16: =IF(H16="WR",1,0) -> 1 | Y16: =IF(H16="TE",1,0) -> 0 | Z16: =IF(OR(H16="RB",H16="WR",H16="TE"),1,0) -> 1 | AA16: 1 | AB16: =VLOOKUP(F16,[1]pff_ppr_projections!$B:$D,3,FALSE) -> 285.3 | AC16: =VLOOKUP(F16,[2]numberFire_ppr_projections!$A:$B,2,FALSE) -> 298.2 | AD16: =VLOOKUP(F16,[3]rotoballer_ppr_projections!$B:$G,6,FALSE) -> 281 | AE16: =VLOOKUP(F16,[4]ppr!$B:$E,4,FALSE) -> 285.72001 | AF16: =VLOOKUP(F16,[4]half_ppr!$B:$E,4,FALSE) -> 235.4151 | AG16: =VLOOKUP(F16,[4]std!$B:$E,4,FALSE) -> 185.11018 | AH16: =IFERROR(VLOOKUP(F16,[5]actual_week11_ppr_stats!$A:$B,2,FALSE),0) -> 195.3
A17: 16 | B17: 20292 | C17: Brown, Chase | D17: {=_xlfn.TEXTSPLIT(C17, ", ")} -> Brown | E17: Chase | F17: =_xlfn.REGEXREPLACE(E17 & " " & D17, "\.", "") -> Chase Brown | G17: CIN | H17: RB | I17: 16.76 | J17: 11 | K17: 25 | L17: =VLOOKUP(G17,byes!$A:$B,2,FALSE) -> 10 | M17: =IF(L17=5,1,0) -> 0 | N17: =IF(L17=6,1,0) -> 0 | O17: =IF(L17=7,1,0) -> 0 | P17: =IF(L17=8,1,0) -> 0 | Q17: =IF(L17=9,1,0) -> 0 | R17: =IF(L17=10,1,0) -> 1 | S17: =IF(L17=11,1,0) -> 0 | T17: =IF(L17=12,1,0) -> 0 | U17: =IF(L17=14,1,0) -> 0 | V17: =IF(H17="QB", 1, 0) -> 0 | W17: =IF(H17="RB",1,0) -> 1 | X17: =IF(H17="WR",1,0) -> 0 | Y17: =IF(H17="TE",1,0) -> 0 | Z17: =IF(OR(H17="RB",H17="WR",H17="TE"),1,0) -> 1 | AA17: =IF(OR(H17="RB",H17="WR",H17="TE", H17="QB"),1,0) -> 1 | AB17: =VLOOKUP(F17,[1]pff_ppr_projections!$B:$D,3,FALSE) -> 225.9 | AC17: =VLOOKUP(F17,[2]numberFire_ppr_projections!$A:$B,2,FALSE) -> 222.5 | AD17: =VLOOKUP(F17,[3]rotoballer_ppr_projections!$B:$G,6,FALSE) -> 258 | AE17: =VLOOKUP(F17,[4]ppr!$B:$E,4,FALSE) -> 257.50168 | AF17: =VLOOKUP(F17,[4]half_ppr!$B:$E,4,FALSE) -> 232.309 | AG17: =VLOOKUP(F17,[4]std!$B:$E,4,FALSE) -> 207.11632 | AH17: =IFERROR(VLOOKUP(F17,[5]actual_week11_ppr_stats!$A:$B,2,FALSE),0) -> 131.8
A18: 17 | B18: 20284 | C18: Achane, De'Von | D18: {=_xlfn.TEXTSPLIT(C18, ", ")} -> Achane | E18: De'Von | F18: =_xlfn.REGEXREPLACE(E18 & " " & D18, "\.", "") -> De'Von Achane | G18: MIA | H18: RB | I18: 18.17 | J18: 12 | K18: 27 | L18: =VLOOKUP(G18,byes!$A:$B,2,FALSE) -> 12 | M18: =IF(L18=5,1,0) -> 0 | N18: =IF(L18=6,1,0) -> 0 | O18: =IF(L18=7,1,0) -> 0 | P18: =IF(L18=8,1,0) -> 0 | Q18: =IF(L18=9,1,0) -> 0 | R18: =IF(L18=10,1,0) -> 0 | S18: =IF(L18=11,1,0) -> 0 | T18: =IF(L18=12,1,0) -> 1 | U18: =IF(L18=14,1,0) -> 0 | V18: =IF(H18="QB", 1, 0) -> 0 | W18: =IF(H18="RB",1,0) -> 1 | X18: =IF(H18="WR",1,0) -> 0 | Y18: =IF(H18="TE",1,0) -> 0 | Z18: =IF(OR(H18="RB",H18="WR",H18="TE"),1,0) -> 1 | AA18: 1 | AB18: =VLOOKUP(F18,[1]pff_ppr_projections!$B:$D,3,FALSE) -> 275.6 | AC18: =VLOOKUP(F18,[2]numberFire_ppr_projections!$A:$B,2,FALSE) -> 299.2 | AD18: =VLOOKUP(F18,[3]rotoballer_ppr_projections!$B:$G,6,FALSE) -> 276 | AE18: =VLOOKUP(F18,[4]ppr!$B:$E,4,FALSE) -> 284.60498 | AF18: =VLOOKUP(F18,[4]half_ppr!$B:$E,4,FALSE) -> 249.3592 | AG18: =VLOOKUP(F18,[4]std!$B:$E,4,FALSE) -> 214.11342 | AH18: =IFERROR(VLOOKUP(F18,[5]actual_week11_ppr_stats!$A:$B,2,FALSE),0) -> 235
A19: 18 | B19: 16998 | C19: Jacobs, Josh | D19: {=_xlfn.TEXTSPLIT(C19, ", ")} -> Jacobs | E19: Josh | F19: =_xlfn.REGEXREPLACE(E19 & " " & D19, "\.", "") -> Josh Jacobs | G19: GB | H19: RB | I19: 19.66 | J19: 14 | K19: 26 | L19: =VLOOKUP(G19,byes!$A:$B,2,FALSE) -> 5 | M19: =IF(L19=5,1,0) -> 1 | N19: =IF(L19=6,1,0) -> 0 | O19: =IF(L19=7,1,0) -> 0 | P19: =IF(L19=8,1,0) -> 0 | Q19: =IF(L19=9,1,0) -> 0 | R19: =IF(L19=10,1,0) -> 0 | S19: =IF(L19=11,1,0) -> 0 | T19: =IF(L19=12,1,0) -> 0 | U19: =IF(L19=14,1,0) -> 0 | V19: =IF(H19="QB", 1, 0) -> 0 | W19: =IF(H19="RB",1,0) -> 1 | X19: =IF(H19="WR",1,0) -> 0 | Y19: =IF(H19="TE",1,0) -> 0 | Z19: =IF(OR(H19="RB",H19="WR",H19="TE"),1,0) -> 1 | AA19: 1 | AB19: =VLOOKUP(F19,[1]pff_ppr_projections!$B:$D,3,FALSE) -> 252 | AC19: =VLOOKUP(F19,[2]numberFire_ppr_projections!$A:$B,2,FALSE) -> 227.9 | AD19: =VLOOKUP(F19,[3]rotoballer_ppr_projections!$B:$G,6,FALSE) -> 259 | AE19: =VLOOKUP(F19,[4]ppr!$B:$E,4,FALSE) -> 267.47567 | AF19: =VLOOKUP(F19,[4]half_ppr!$B:$E,4,FALSE) -> 250.07548 | AG19: =VLOOKUP(F19,[4]std!$B:$E,4,FALSE) -> 232.67528 | AH19: =IFERROR(VLOOKUP(F19,[5]actual_week11_ppr_stats!$A:$B,2,FALSE),0) -> 182.5
A20: 19 | B20: 17004 | C20: Brown, A.J. | D20: {=_xlfn.TEXTSPLIT(C20, ", ")} -> Brown | E20: A.J. | F20: =_xlfn.REGEXREPLACE(E20 & " " & D20, "\.", "") -> AJ Brown | G20: PHI | H20: WR | I20: 19.75 | J20: 14 | K20: 26 | L20: =VLOOKUP(G20,byes!$A:$B,2,FALSE) -> 9 | M20: =IF(L20=5,1,0) -> 0 | N20: =IF(L20=6,1,0) -> 0 | O20: =IF(L20=7,1,0) -> 0 | P20: =IF(L20=8,1,0) -> 0 | Q20: =IF(L20=9,1,0) -> 1 | R20: =IF(L20=10,1,0) -> 0 | S20: =IF(L20=11,1,0) -> 0 | T20: =IF(L20=12,1,0) -> 0 | U20: =IF(L20=14,1,0) -> 0 | V20: =IF(H20="QB", 1, 0) -> 0 | W20: =IF(H20="RB",1,0) -> 0 | X20: =IF(H20="WR",1,0) -> 1 | Y20: =IF(H20="TE",1,0) -> 0 | Z20: =IF(OR(H20="RB",H20="WR",H20="TE"),1,0) -> 1 | AA20: 1 | AB20: =VLOOKUP(F20,[1]pff_ppr_projections!$B:$D,3,FALSE) -> 255.7 | AC20: =VLOOKUP(F20,[2]numberFire_ppr_projections!$A:$B,2,FALSE) -> 270.6 | AD20: =VLOOKUP(F20,[3]rotoballer_ppr_projections!$B:$G,6,FALSE) -> 261 | AE20: =VLOOKUP(F20,[4]ppr!$B:$E,4,FALSE) -> 229.76602 | AF20: =VLOOKUP(F20,[4]half_ppr!$B:$E,4,FALSE) -> 192.51472 | AG20: =VLOOKUP(F20,[4]std!$B:$E,4,FALSE) -> 155.26342 | AH20: =IFERROR(VLOOKUP(F20,[5]actual_week11_ppr_stats!$A:$B,2,FALSE),0) -> 101.7
A21: 20 | B21: 17962 | C21: Taylor, Jonathan | D21: {=_xlfn.TEXTSPLIT(C21, ", ")} -> Taylor | E21: Jonathan | F21: =_xlfn.REGEXREPLACE(E21 & " " & D21, "\.", "") -> Jonathan Taylor | G21: IND | H21: RB | I21: 19.97 | J21: 13 | K21: 28 | L21: =VLOOKUP(G21,byes!$A:$B,2,FALSE) -> 11 | M21: =IF(L21=5,1,0) -> 0 | N21: =IF(L21=6,1,0) -> 0 | O21: =IF(L21=7,1,0) -> 0 | P21: =IF(L21=8,1,0) -> 0 | Q21: =IF(L21=9,1,0) -> 0 | R21: =IF(L21=10,1,0) -> 0 | S21: =IF(L21=11,1,0) -> 1 | T21: =IF(L21=12,1,0) -> 0 | U21: =IF(L21=14,1,0) -> 0 | V21: =IF(H21="QB", 1, 0) -> 0 | W21: =IF(H21="RB",1,0) -> 1 | X21: =IF(H21="WR",1,0) -> 0 | Y21: =IF(H21="TE",1,0) -> 0 | Z21: =IF(OR(H21="RB",H21="WR",H21="TE"),1,0) -> 1 | AA21: =IF(OR(H21="RB",H21="WR",H21="TE", H21="QB"),1,0) -> 1 | AB21: =VLOOKUP(F21,[1]pff_ppr_projections!$B:$D,3,FALSE) -> 242.7 | AC21: =VLOOKUP(F21,[2]numberFire_ppr_projections!$A:$B,2,FALSE) -> 210.6 | AD21: =VLOOKUP(F21,[3]rotoballer_ppr_projections!$B:$G,6,FALSE) -> 263 | AE21: =VLOOKUP(F21,[4]ppr!$B:$E,4,FALSE) -> 253.11796 | AF21: =VLOOKUP(F21,[4]half_ppr!$B:$E,4,FALSE) -> 239.62629 | AG21: =VLOOKUP(F21,[4]std!$B:$E,4,FALSE) -> 226.13463 | AH21: =IFERROR(VLOOKUP(F21,[5]actual_week11_ppr_stats!$A:$B,2,FALSE),0) -> 271.9
A22: 21 | B22: 21136 | C22: Irving, Bucky | D22: {=_xlfn.TEXTSPLIT(C22, ", ")} -> Irving | E22: Bucky | F22: =_xlfn.REGEXREPLACE(E22 & " " & D22, "\.", "") -> Bucky Irving | G22: TB | H22: RB | I22: 20.04 | J22: 11 | K22: 31 | L22: =VLOOKUP(G22,byes!$A:$B,2,FALSE) -> 9 | M22: =IF(L22=5,1,0) -> 0 | N22: =IF(L22=6,1,0) -> 0 | O22: =IF(L22=7,1,0) -> 0 | P22: =IF(L22=8,1,0) -> 0 | Q22: =IF(L22=9,1,0) -> 1 | R22: =IF(L22=10,1,0) -> 0 | S22: =IF(L22=11,1,0) -> 0 | T22: =IF(L22=12,1,0) -> 0 | U22: =IF(L22=14,1,0) -> 0 | V22: =IF(H22="QB", 1, 0) -> 0 | W22: =IF(H22="RB",1,0) -> 1 | X22: =IF(H22="WR",1,0) -> 0 | Y22: =IF(H22="TE",1,0) -> 0 | Z22: =IF(OR(H22="RB",H22="WR",H22="TE"),1,0) -> 1 | AA22: 1 | AB22: =VLOOKUP(F22,[1]pff_ppr_projections!$B:$D,3,FALSE) -> 281.8 | AC22: =VLOOKUP(F22,[2]numberFire_ppr_projections!$A:$B,2,FALSE) -> 212.2 | AD22: =VLOOKUP(F22,[3]rotoballer_ppr_projections!$B:$G,6,FALSE) -> 259 | AE22: =VLOOKUP(F22,[4]ppr!$B:$E,4,FALSE) -> 284.75845 | AF22: =VLOOKUP(F22,[4]half_ppr!$B:$E,4,FALSE) -> 262.67425 | AG22: =VLOOKUP(F22,[4]std!$B:$E,4,FALSE) -> 240.59005 | AH22: =IFERROR(VLOOKUP(F22,[5]actual_week11_ppr_stats!$A:$B,2,FALSE),0) -> 74
A23: 22 | B23: 21123 | C23: Bowers, Brock | D23: {=_xlfn.TEXTSPLIT(C23, ", ")} -> Bowers | E23: Brock | F23: =_xlfn.REGEXREPLACE(E23 & " " & D23, "\.", "") -> Brock Bowers | G23: LV | H23: TE | I23: 20.75 | J23: 13 | K23: 29 | L23: =VLOOKUP(G23,byes!$A:$B,2,FALSE) -> 8 | M23: =IF(L23=5,1,0) -> 0 | N23: =IF(L23=6,1,0) -> 0 | O23: =IF(L23=7,1,0) -> 0 | P23: =IF(L23=8,1,0) -> 1 | Q23: =IF(L23=9,1,0) -> 0 | R23: =IF(L23=10,1,0) -> 0 | S23: =IF(L23=11,1,0) -> 0 | T23: =IF(L23=12,1,0) -> 0 | U23: =IF(L23=14,1,0) -> 0 | V23: =IF(H23="QB", 1, 0) -> 0 | W23: =IF(H23="RB",1,0) -> 0 | X23: =IF(H23="WR",1,0) -> 0 | Y23: =IF(H23="TE",1,0) -> 1 | Z23: =IF(OR(H23="RB",H23="WR",H23="TE"),1,0) -> 1 | AA23: 1 | AB23: =VLOOKUP(F23,[1]pff_ppr_projections!$B:$D,3,FALSE) -> 245.9 | AC23: =VLOOKUP(F23,[2]numberFire_ppr_projections!$A:$B,2,FALSE) -> 270.6 | AD23: =VLOOKUP(F23,[3]rotoballer_ppr_projections!$B:$G,6,FALSE) -> 257 | AE23: =VLOOKUP(F23,[4]ppr!$B:$E,4,FALSE) -> 263.9926 | AF23: =VLOOKUP(F23,[4]half_ppr!$B:$E,4,FALSE) -> 211.38347 | AG23: =VLOOKUP(F23,[4]std!$B:$E,4,FALSE) -> 158.77434 | AH23: =IFERROR(VLOOKUP(F23,[5]actual_week11_ppr_stats!$A:$B,2,FALSE),0) -> 102.7
A24: 23 | B24: 21139 | C24: McConkey, Ladd | D24: {=_xlfn.TEXTSPLIT(C24, ", ")} -> McConkey | E24: Ladd | F24: =_xlfn.REGEXREPLACE(E24 & " " & D24, "\.", "") -> Ladd McConkey | G24: LAC | H24: WR | I24: 22 | J24: 14 | K24: 29 | L24: =VLOOKUP(G24,byes!$A:$B,2,FALSE) -> 12 | M24: =IF(L24=5,1,0) -> 0 | N24: =IF(L24=6,1,0) -> 0 | O24: =IF(L24=7,1,0) -> 0 | P24: =IF(L24=8,1,0) -> 0 | Q24: =IF(L24=9,1,0) -> 0 | R24: =IF(L24=10,1,0) -> 0 | S24: =IF(L24=11,1,0) -> 0 | T24: =IF(L24=12,1,0) -> 1 | U24: =IF(L24=14,1,0) -> 0 | V24: =IF(H24="QB", 1, 0) -> 0 | W24: =IF(H24="RB",1,0) -> 0 | X24: =IF(H24="WR",1,0) -> 1 | Y24: =IF(H24="TE",1,0) -> 0 | Z24: =IF(OR(H24="RB",H24="WR",H24="TE"),1,0) -> 1 | AA24: 1 | AB24: =VLOOKUP(F24,[1]pff_ppr_projections!$B:$D,3,FALSE) -> 249.7 | AC24: =VLOOKUP(F24,[2]numberFire_ppr_projections!$A:$B,2,FALSE) -> 284.3 | AD24: =VLOOKUP(F24,[3]rotoballer_ppr_projections!$B:$G,6,FALSE) -> 245 | AE24: =VLOOKUP(F24,[4]ppr!$B:$E,4,FALSE) -> 246.37288 | AF24: =VLOOKUP(F24,[4]half_ppr!$B:$E,4,FALSE) -> 202.14076 | AG24: =VLOOKUP(F24,[4]std!$B:$E,4,FALSE) -> 157.90865 | AH24: =IFERROR(VLOOKUP(F24,[5]actual_week11_ppr_stats!$A:$B,2,FALSE),0) -> 142.4
A25: 24 | B25: 20273 | C25: Smith-Njigba, Jaxon | D25: {=_xlfn.TEXTSPLIT(C25, ", ")} -> Smith-Njigba | E25: Jaxon | F25: =_xlfn.REGEXREPLACE(E25 & " " & D25, "\.", "") -> Jaxon Smith-Njigba | G25: SEA | H25: WR | I25: 26.5 | J25: 21 | K25: 35 | L25: =VLOOKUP(G25,byes!$A:$B,2,FALSE) -> 8 | M25: =IF(L25=5,1,0) -> 0 | N25: =IF(L25=6,1,0) -> 0 | O25: =IF(L25=7,1,0) -> 0 | P25: =IF(L25=8,1,0) -> 1 | Q25: =IF(L25=9,1,0) -> 0 | R25: =IF(L25=10,1,0) -> 0 | S25: =IF(L25=11,1,0) -> 0 | T25: =IF(L25=12,1,0) -> 0 | U25: =IF(L25=14,1,0) -> 0 | V25: =IF(H25="QB", 1, 0) -> 0 | W25: =IF(H25="RB",1,0) -> 0 | X25: =IF(H25="WR",1,0) -> 1 | Y25: =IF(H25="TE",1,0) -> 0 | Z25: =IF(OR(H25="RB",H25="WR",H25="TE"),1,0) -> 1 | AA25: =IF(OR(H25="RB",H25="WR",H25="TE", H25="QB"),1,0) -> 1 | AB25: =VLOOKUP(F25,[1]pff_ppr_projections!$B:$D,3,FALSE) -> 217.9 | AC25: =VLOOKUP(F25,[2]numberFire_ppr_projections!$A:$B,2,FALSE) -> 279.3 | AD25: =VLOOKUP(F25,[3]rotoballer_ppr_projections!$B:$G,6,FALSE) -> 250 | AE25: =VLOOKUP(F25,[4]ppr!$B:$E,4,FALSE) -> 264.97753 | AF25: =VLOOKUP(F25,[4]half_ppr!$B:$E,4,FALSE) -> 217.28539 | AG25: =VLOOKUP(F25,[4]std!$B:$E,4,FALSE) -> 169.59325 | AH25: =IFERROR(VLOOKUP(F25,[5]actual_week11_ppr_stats!$A:$B,2,FALSE),0) -> 219.9
A26: 25 | B26: 17971 | C26: Higgins, Tee | D26: {=_xlfn.TEXTSPLIT(C26, ", ")} -> Higgins | E26: Tee | F26: =_xlfn.REGEXREPLACE(E26 & " " & D26, "\.", "") -> Tee Higgins | G26: CIN | H26: WR | I26: 27.2 | J26: 17 | K26: 35 | L26: =VLOOKUP(G26,byes!$A:$B,2,FALSE) -> 10 | M26: =IF(L26=5,1,0) -> 0 | N26: =IF(L26=6,1,0) -> 0 | O26: =IF(L26=7,1,0) -> 0 | P26: =IF(L26=8,1,0) -> 0 | Q26: =IF(L26=9,1,0) -> 0 | R26: =IF(L26=10,1,0) -> 1 | S26: =IF(L26=11,1,0) -> 0 | T26: =IF(L26=12,1,0) -> 0 | U26: =IF(L26=14,1,0) -> 0 | V26: =IF(H26="QB", 1, 0) -> 0 | W26: =IF(H26="RB",1,0) -> 0 | X26: =IF(H26="WR",1,0) -> 1 | Y26: =IF(H26="TE",1,0) -> 0 | Z26: =IF(OR(H26="RB",H26="WR",H26="TE"),1,0) -> 1 | AA26: 1 | AB26: =VLOOKUP(F26,[1]pff_ppr_projections!$B:$D,3,FALSE) -> 245.7 | AC26: =VLOOKUP(F26,[2]numberFire_ppr_projections!$A:$B,2,FALSE) -> 263.6 | AD26: =VLOOKUP(F26,[3]rotoballer_ppr_projections!$B:$G,6,FALSE) -> 257 | AE26: =VLOOKUP(F26,[4]ppr!$B:$E,4,FALSE) -> 257.99093 | AF26: =VLOOKUP(F26,[4]half_ppr!$B:$E,4,FALSE) -> 214.08506 | AG26: =VLOOKUP(F26,[4]std!$B:$E,4,FALSE) -> 170.17918 | AH26: =IFERROR(VLOOKUP(F26,[5]actual_week11_ppr_stats!$A:$B,2,FALSE),0) -> 131.4
A27: 26 | B27: 19450 | C27: Williams, Kyren | D27: {=_xlfn.TEXTSPLIT(C27, ", ")} -> Williams | E27: Kyren | F27: =_xlfn.REGEXREPLACE(E27 & " " & D27, "\.", "") -> Kyren Williams | G27: LA | H27: RB | I27: 27.34 | J27: 17 | K27: 43 | L27: =VLOOKUP(G27,byes!$A:$B,2,FALSE) -> 8 | M27: =IF(L27=5,1,0) -> 0 | N27: =IF(L27=6,1,0) -> 0 | O27: =IF(L27=7,1,0) -> 0 | P27: =IF(L27=8,1,0) -> 1 | Q27: =IF(L27=9,1,0) -> 0 | R27: =IF(L27=10,1,0) -> 0 | S27: =IF(L27=11,1,0) -> 0 | T27: =IF(L27=12,1,0) -> 0 | U27: =IF(L27=14,1,0) -> 0 | V27: =IF(H27="QB", 1, 0) -> 0 | W27: =IF(H27="RB",1,0) -> 1 | X27: =IF(H27="WR",1,0) -> 0 | Y27: =IF(H27="TE",1,0) -> 0 | Z27: =IF(OR(H27="RB",H27="WR",H27="TE"),1,0) -> 1 | AA27: 1 | AB27: =VLOOKUP(F27,[1]pff_ppr_projections!$B:$D,3,FALSE) -> 241.9 | AC27: =VLOOKUP(F27,[2]numberFire_ppr_projections!$A:$B,2,FALSE) -> 208.4 | AD27: =VLOOKUP(F27,[3]rotoballer_ppr_projections!$B:$G,6,FALSE) -> 245 | AE27: =VLOOKUP(F27,[4]ppr!$B:$E,4,FALSE) -> 253.03848 | AF27: =VLOOKUP(F27,[4]half_ppr!$B:$E,4,FALSE) -> 238.93116 | AG27: =VLOOKUP(F27,[4]std!$B:$E,4,FALSE) -> 224.82383 | AH27: =IFERROR(VLOOKUP(F27,[5]actual_week11_ppr_stats!$A:$B,2,FALSE),0) -> 170.2
A28: 27 | B28: 19439 | C28: McBride, Trey | D28: {=_xlfn.TEXTSPLIT(C28, ", ")} -> McBride | E28: Trey | F28: =_xlfn.REGEXREPLACE(E28 & " " & D28, "\.", "") -> Trey McBride | G28: ARZ | H28: TE | I28: 28 | J28: 20 | K28: 40 | L28: =VLOOKUP(G28,byes!$A:$B,2,FALSE) -> 8 | M28: =IF(L28=5,1,0) -> 0 | N28: =IF(L28=6,1,0) -> 0 | O28: =IF(L28=7,1,0) -> 0 | P28: =IF(L28=8,1,0) -> 1 | Q28: =IF(L28=9,1,0) -> 0 | R28: =IF(L28=10,1,0) -> 0 | S28: =IF(L28=11,1,0) -> 0 | T28: =IF(L28=12,1,0) -> 0 | U28: =IF(L28=14,1,0) -> 0 | V28: =IF(H28="QB", 1, 0) -> 0 | W28: =IF(H28="RB",1,0) -> 0 | X28: =IF(H28="WR",1,0) -> 0 | Y28: =IF(H28="TE",1,0) -> 1 | Z28: =IF(OR(H28="RB",H28="WR",H28="TE"),1,0) -> 1 | AA28: 1 | AB28: =VLOOKUP(F28,[1]pff_ppr_projections!$B:$D,3,FALSE) -> 235.9 | AC28: =VLOOKUP(F28,[2]numberFire_ppr_projections!$A:$B,2,FALSE) -> 242 | AD28: =VLOOKUP(F28,[3]rotoballer_ppr_projections!$B:$G,6,FALSE) -> 234 | AE28: =VLOOKUP(F28,[4]ppr!$B:$E,4,FALSE) -> 243.64618 | AF28: =VLOOKUP(F28,[4]half_ppr!$B:$E,4,FALSE) -> 193.69821 | AG28: =VLOOKUP(F28,[4]std!$B:$E,4,FALSE) -> 143.75025 | AH28: =IFERROR(VLOOKUP(F28,[5]actual_week11_ppr_stats!$A:$B,2,FALSE),0) -> 184.8
A29: 28 | B29: 16081 | C29: Jackson, Lamar | D29: {=_xlfn.TEXTSPLIT(C29, ", ")} -> Jackson | E29: Lamar | F29: =_xlfn.REGEXREPLACE(E29 & " " & D29, "\.", "") -> Lamar Jackson | G29: BAL | H29: QB | I29: 28.91 | J29: 17 | K29: 38 | L29: =VLOOKUP(G29,byes!$A:$B,2,FALSE) -> 7 | M29: =IF(L29=5,1,0) -> 0 | N29: =IF(L29=6,1,0) -> 0 | O29: =IF(L29=7,1,0) -> 1 | P29: =IF(L29=8,1,0) -> 0 | Q29: =IF(L29=9,1,0) -> 0 | R29: =IF(L29=10,1,0) -> 0 | S29: =IF(L29=11,1,0) -> 0 | T29: =IF(L29=12,1,0) -> 0 | U29: =IF(L29=14,1,0) -> 0 | V29: =IF(H29="QB", 1, 0) -> 1 | W29: =IF(H29="RB",1,0) -> 0 | X29: =IF(H29="WR",1,0) -> 0 | Y29: =IF(H29="TE",1,0) -> 0 | Z29: =IF(OR(H29="RB",H29="WR",H29="TE"),1,0) -> 0 | AA29: =IF(OR(H29="RB",H29="WR",H29="TE", H29="QB"),1,0) -> 1 | AB29: =VLOOKUP(F29,[1]pff_ppr_projections!$B:$D,3,FALSE) -> 338.5 | AC29: =VLOOKUP(F29,[2]numberFire_ppr_projections!$A:$B,2,FALSE) -> 384.1 | AD29: =VLOOKUP(F29,[3]rotoballer_ppr_projections!$B:$G,6,FALSE) -> 359 | AE29: =VLOOKUP(F29,[4]ppr!$B:$E,4,FALSE) -> 382.58688 | AF29: =VLOOKUP(F29,[4]half_ppr!$B:$E,4,FALSE) -> 382.58688 | AG29: =VLOOKUP(F29,[4]std!$B:$E,4,FALSE) -> 382.58688 | AH29: =IFERROR(VLOOKUP(F29,[5]actual_week11_ppr_stats!$A:$B,2,FALSE),0) -> 143.3
A30: 29 | B30: 22069 | C30: Hampton, Omarion | D30: {=_xlfn.TEXTSPLIT(C30, ", ")} -> Hampton | E30: Omarion | F30: =_xlfn.REGEXREPLACE(E30 & " " & D30, "\.", "") -> Omarion Hampton | G30: LAC | H30: RB | I30: 30.17 | J30: 8 | K30: 46 | L30: =VLOOKUP(G30,byes!$A:$B,2,FALSE) -> 12 | M30: =IF(L30=5,1,0) -> 0 | N30: =IF(L30=6,1,0) -> 0 | O30: =IF(L30=7,1,0) -> 0 | P30: =IF(L30=8,1,0) -> 0 | Q30: =IF(L30=9,1,0) -> 0 | R30: =IF(L30=10,1,0) -> 0 | S30: =IF(L30=11,1,0) -> 0 | T30: =IF(L30=12,1,0) -> 1 | U30: =IF(L30=14,1,0) -> 0 | V30: =IF(H30="QB", 1, 0) -> 0 | W30: =IF(H30="RB",1,0) -> 1 | X30: =IF(H30="WR",1,0) -> 0 | Y30: =IF(H30="TE",1,0) -> 0 | Z30: =IF(OR(H30="RB",H30="WR",H30="TE"),1,0) -> 1 | AA30: 1 | AB30: =VLOOKUP(F30,[1]pff_ppr_projections!$B:$D,3,FALSE) -> 227.9 | AC30: =VLOOKUP(F30,[2]numberFire_ppr_projections!$A:$B,2,FALSE) -> 206.7 | AD30: =VLOOKUP(F30,[3]rotoballer_ppr_projections!$B:$G,6,FALSE) -> 207 | AE30: =VLOOKUP(F30,[4]ppr!$B:$E,4,FALSE) -> 241.51948 | AF30: =VLOOKUP(F30,[4]half_ppr!$B:$E,4,FALSE) -> 225.64364 | AG30: =VLOOKUP(F30,[4]std!$B:$E,4,FALSE) -> 209.76781 | AH30: =IFERROR(VLOOKUP(F30,[5]actual_week11_ppr_stats!$A:$B,2,FALSE),0) -> 77
A31: 30 | B31: 16074 | C31: Allen, Josh | D31: {=_xlfn.TEXTSPLIT(C31, ", ")} -> Allen | E31: Josh | F31: =_xlfn.REGEXREPLACE(E31 & " " & D31, "\.", "") -> Josh Allen | G31: BUF | H31: QB | I31: 30.8 | J31: 23 | K31: 42 | L31: =VLOOKUP(G31,byes!$A:$B,2,FALSE) -> 7 | M31: =IF(L31=5,1,0) -> 0 | N31: =IF(L31=6,1,0) -> 0 | O31: =IF(L31=7,1,0) -> 1 | P31: =IF(L31=8,1,0) -> 0 | Q31: =IF(L31=9,1,0) -> 0 | R31: =IF(L31=10,1,0) -> 0 | S31: =IF(L31=11,1,0) -> 0 | T31: =IF(L31=12,1,0) -> 0 | U31: =IF(L31=14,1,0) -> 0 | V31: =IF(H31="QB", 1, 0) -> 1 | W31: =IF(H31="RB",1,0) -> 0 | X31: =IF(H31="WR",1,0) -> 0 | Y31: =IF(H31="TE",1,0) -> 0 | Z31: =IF(OR(H31="RB",H31="WR",H31="TE"),1,0) -> 0 | AA31: 1 | AB31: =VLOOKUP(F31,[1]pff_ppr_projections!$B:$D,3,FALSE) -> 341.4 | AC31: =VLOOKUP(F31,[2]numberFire_ppr_projections!$A:$B,2,FALSE) -> 384.1 | AD31: =VLOOKUP(F31,[3]rotoballer_ppr_projections!$B:$G,6,FALSE) -> 362 | AE31: =VLOOKUP(F31,[4]ppr!$B:$E,4,FALSE) -> 370.47445 | AF31: =VLOOKUP(F31,[4]half_ppr!$B:$E,4,FALSE) -> 370.47445 | AG31: =VLOOKUP(F31,[4]std!$B:$E,4,FALSE) -> 370.47445 | AH31: =IFERROR(VLOOKUP(F31,[5]actual_week11_ppr_stats!$A:$B,2,FALSE),0) -> 268.5
A32: 31 | B32: 19431 | C32: Wilson, Garrett | D32: {=_xlfn.TEXTSPLIT(C32, ", ")} -> Wilson | E32: Garrett | F32: =_xlfn.REGEXREPLACE(E32 & " " & D32, "\.", "") -> Garrett Wilson | G32: NYJ | H32: WR | I32: 32.08 | J32: 19 | K32: 45 | L32: =VLOOKUP(G32,byes!$A:$B,2,FALSE) -> 9 | M32: =IF(L32=5,1,0) -> 0 | N32: =IF(L32=6,1,0) -> 0 | O32: =IF(L32=7,1,0) -> 0 | P32: =IF(L32=8,1,0) -> 0 | Q32: =IF(L32=9,1,0) -> 1 | R32: =IF(L32=10,1,0) -> 0 | S32: =IF(L32=11,1,0) -> 0 | T32: =IF(L32=12,1,0) -> 0 | U32: =IF(L32=14,1,0) -> 0 | V32: =IF(H32="QB", 1, 0) -> 0 | W32: =IF(H32="RB",1,0) -> 0 | X32: =IF(H32="WR",1,0) -> 1 | Y32: =IF(H32="TE",1,0) -> 0 | Z32: =IF(OR(H32="RB",H32="WR",H32="TE"),1,0) -> 1 | AA32: 1 | AB32: =VLOOKUP(F32,[1]pff_ppr_projections!$B:$D,3,FALSE) -> 239.6 | AC32: =VLOOKUP(F32,[2]numberFire_ppr_projections!$A:$B,2,FALSE) -> 242.9 | AD32: =VLOOKUP(F32,[3]rotoballer_ppr_projections!$B:$G,6,FALSE) -> 237 | AE32: =VLOOKUP(F32,[4]ppr!$B:$E,4,FALSE) -> 223.8641 | AF32: =VLOOKUP(F32,[4]half_ppr!$B:$E,4,FALSE) -> 182.77304 | AG32: =VLOOKUP(F32,[4]std!$B:$E,4,FALSE) -> 141.68198 | AH32: =IFERROR(VLOOKUP(F32,[5]actual_week11_ppr_stats!$A:$B,2,FALSE),0) -> 99.5
A33: 32 | B33: 21121 | C33: Harrison Jr., Marvin | D33: {=_xlfn.TEXTSPLIT(C33, ", ")} -> Harrison Jr. | E33: Marvin | F33: =_xlfn.REGEXREPLACE(E33 & " " & D33, "\.", "") -> Marvin Harrison Jr | G33: ARZ | H33: WR | I33: 33.5 | J33: 22 | K33: 51 | L33: =VLOOKUP(G33,byes!$A:$B,2,FALSE) -> 8 | M33: =IF(L33=5,1,0) -> 0 | N33: =IF(L33=6,1,0) -> 0 | O33: =IF(L33=7,1,0) -> 0 | P33: =IF(L33=8,1,0) -> 1 | Q33: =IF(L33=9,1,0) -> 0 | R33: =IF(L33=10,1,0) -> 0 | S33: =IF(L33=11,1,0) -> 0 | T33: =IF(L33=12,1,0) -> 0 | U33: =IF(L33=14,1,0) -> 0 | V33: =IF(H33="QB", 1, 0) -> 0 | W33: =IF(H33="RB",1,0) -> 0 | X33: =IF(H33="WR",1,0) -> 1 | Y33: =IF(H33="TE",1,0) -> 0 | Z33: =IF(OR(H33="RB",H33="WR",H33="TE"),1,0) -> 1 | AA33: =IF(OR(H33="RB",H33="WR",H33="TE", H33="QB"),1,0) -> 1 | AB33: =VLOOKUP(F33,[1]pff_ppr_projections!$B:$D,3,FALSE) -> 233.1 | AC33: =VLOOKUP(F33,[2]numberFire_ppr_projections!$A:$B,2,FALSE) -> 264.8 | AD33: =VLOOKUP(F33,[3]rotoballer_ppr_projections!$B:$G,6,FALSE) -> 226 | AE33: =VLOOKUP(F33,[4]ppr!$B:$E,4,FALSE) -> 215.12763 | AF33: =VLOOKUP(F33,[4]half_ppr!$B:$E,4,FALSE) -> 176.25383 | AG33: =VLOOKUP(F33,[4]std!$B:$E,4,FALSE) -> 137.38003 | AH33: =IFERROR(VLOOKUP(F33,[5]actual_week11_ppr_stats!$A:$B,2,FALSE),0) -> 110.5
A34: 33 | B34: 22072 | C34: Henderson, TreVeyon | D34: {=_xlfn.TEXTSPLIT(C34, ", ")} -> Henderson | E34: TreVeyon | F34: =_xlfn.REGEXREPLACE(E34 & " " & D34, "\.", "") -> TreVeyon Henderson | G34: NE | H34: RB | I34: 34.22 | J34: 21 | K34: 49 | L34: =VLOOKUP(G34,byes!$A:$B,2,FALSE) -> 14 | M34: =IF(L34=5,1,0) -> 0 | N34: =IF(L34=6,1,0) -> 0 | O34: =IF(L34=7,1,0) -> 0 | P34: =IF(L34=8,1,0) -> 0 | Q34: =IF(L34=9,1,0) -> 0 | R34: =IF(L34=10,1,0) -> 0 | S34: =IF(L34=11,1,0) -> 0 | T34: =IF(L34=12,1,0) -> 0 | U34: =IF(L34=14,1,0) -> 1 | V34: =IF(H34="QB", 1, 0) -> 0 | W34: =IF(H34="RB",1,0) -> 1 | X34: =IF(H34="WR",1,0) -> 0 | Y34: =IF(H34="TE",1,0) -> 0 | Z34: =IF(OR(H34="RB",H34="WR",H34="TE"),1,0) -> 1 | AA34: 1 | AB34: =VLOOKUP(F34,[1]pff_ppr_projections!$B:$D,3,FALSE) -> 166.4 | AC34: =VLOOKUP(F34,[2]numberFire_ppr_projections!$A:$B,2,FALSE) -> 159.7 | AD34: =VLOOKUP(F34,[3]rotoballer_ppr_projections!$B:$G,6,FALSE) -> 198 | AE34: =VLOOKUP(F34,[4]ppr!$B:$E,4,FALSE) -> 228.1513 | AF34: =VLOOKUP(F34,[4]half_ppr!$B:$E,4,FALSE) -> 202.62759 | AG34: =VLOOKUP(F34,[4]std!$B:$E,4,FALSE) -> 177.10388 | AH34: =IFERROR(VLOOKUP(F34,[5]actual_week11_ppr_stats!$A:$B,2,FALSE),0) -> 127.7
A35: 34 | B35: 14725 | C35: Hill, Tyreek | D35: {=_xlfn.TEXTSPLIT(C35, ", ")} -> Hill | E35: Tyreek | F35: =_xlfn.REGEXREPLACE(E35 & " " & D35, "\.", "") -> Tyreek Hill | G35: MIA | H35: WR | I35: 34.68 | J35: 20 | K35: 46 | L35: =VLOOKUP(G35,byes!$A:$B,2,FALSE) -> 12 | M35: =IF(L35=5,1,0) -> 0 | N35: =IF(L35=6,1,0) -> 0 | O35: =IF(L35=7,1,0) -> 0 | P35: =IF(L35=8,1,0) -> 0 | Q35: =IF(L35=9,1,0) -> 0 | R35: =IF(L35=10,1,0) -> 0 | S35: =IF(L35=11,1,0) -> 0 | T35: =IF(L35=12,1,0) -> 1 | U35: =IF(L35=14,1,0) -> 0 | V35: =IF(H35="QB", 1, 0) -> 0 | W35: =IF(H35="RB",1,0) -> 0 | X35: =IF(H35="WR",1,0) -> 1 | Y35: =IF(H35="TE",1,0) -> 0 | Z35: =IF(OR(H35="RB",H35="WR",H35="TE"),1,0) -> 1 | AA35: 1 | AB35: =VLOOKUP(F35,[1]pff_ppr_projections!$B:$D,3,FALSE) -> 217.9 | AC35: =VLOOKUP(F35,[2]numberFire_ppr_projections!$A:$B,2,FALSE) -> 279.4 | AD35: =AVERAGE(AB35,AC35,AE35) -> 252.21347 | AE35: =VLOOKUP(F35,[4]ppr!$B:$E,4,FALSE) -> 259.3404 | AF35: =VLOOKUP(F35,[4]half_ppr!$B:$E,4,FALSE) -> 216.07226 | AG35: =VLOOKUP(F35,[4]std!$B:$E,4,FALSE) -> 172.80412 | AH35: =IFERROR(VLOOKUP(F35,[5]actual_week11_ppr_stats!$A:$B,2,FALSE),0) -> 53.5
A36: 35 | B36: 19467 | C36: Cook, James | D36: {=_xlfn.TEXTSPLIT(C36, ", ")} -> Cook | E36: James | F36: =_xlfn.REGEXREPLACE(E36 & " " & D36, "\.", "") -> James Cook | G36: BUF | H36: RB | I36: 37.26 | J36: 20 | K36: 51 | L36: =VLOOKUP(G36,byes!$A:$B,2,FALSE) -> 7 | M36: =IF(L36=5,1,0) -> 0 | N36: =IF(L36=6,1,0) -> 0 | O36: =IF(L36=7,1,0) -> 1 | P36: =IF(L36=8,1,0) -> 0 | Q36: =IF(L36=9,1,0) -> 0 | R36: =IF(L36=10,1,0) -> 0 | S36: =IF(L36=11,1,0) -> 0 | T36: =IF(L36=12,1,0) -> 0 | U36: =IF(L36=14,1,0) -> 0 | V36: =IF(H36="QB", 1, 0) -> 0 | W36: =IF(H36="RB",1,0) -> 1 | X36: =IF(H36="WR",1,0) -> 0 | Y36: =IF(H36="TE",1,0) -> 0 | Z36: =IF(OR(H36="RB",H36="WR",H36="TE"),1,0) -> 1 | AA36: 1 | AB36: =VLOOKUP(F36,[1]pff_ppr_projections!$B:$D,3,FALSE) -> 231.7 | AC36: =VLOOKUP(F36,[2]numberFire_ppr_projections!$A:$B,2,FALSE) -> 189.1 | AD36: =VLOOKUP(F36,[3]rotoballer_ppr_projections!$B:$G,6,FALSE) -> 233 | AE36: =VLOOKUP(F36,[4]ppr!$B:$E,4,FALSE) -> 210.17578 | AF36: =VLOOKUP(F36,[4]half_ppr!$B:$E,4,FALSE) -> 195.18879 | AG36: =VLOOKUP(F36,[4]std!$B:$E,4,FALSE) -> 180.20181 | AH36: =IFERROR(VLOOKUP(F36,[5]actual_week11_ppr_stats!$A:$B,2,FALSE),0) -> 206.7
A37: 36 | B37: 22059 | C37: McMillan, Tetairoa | D37: {=_xlfn.TEXTSPLIT(C37, ", ")} -> McMillan | E37: Tetairoa | F37: =_xlfn.REGEXREPLACE(E37 & " " & D37, "\.", "") -> Tetairoa McMillan | G37: CAR | H37: WR | I37: 37.47 | J37: 26 | K37: 51 | L37: =VLOOKUP(G37,byes!$A:$B,2,FALSE) -> 14 | M37: =IF(L37=5,1,0) -> 0 | N37: =IF(L37=6,1,0) -> 0 | O37: =IF(L37=7,1,0) -> 0 | P37: =IF(L37=8,1,0) -> 0 | Q37: =IF(L37=9,1,0) -> 0 | R37: =IF(L37=10,1,0) -> 0 | S37: =IF(L37=11,1,0) -> 0 | T37: =IF(L37=12,1,0) -> 0 | U37: =IF(L37=14,1,0) -> 1 | V37: =IF(H37="QB", 1, 0) -> 0 | W37: =IF(H37="RB",1,0) -> 0 | X37: =IF(H37="WR",1,0) -> 1 | Y37: =IF(H37="TE",1,0) -> 0 | Z37: =IF(OR(H37="RB",H37="WR",H37="TE"),1,0) -> 1 | AA37: =IF(OR(H37="RB",H37="WR",H37="TE", H37="QB"),1,0) -> 1 | AB37: =VLOOKUP(F37,[1]pff_ppr_projections!$B:$D,3,FALSE) -> 216.1 | AC37: =VLOOKUP(F37,[2]numberFire_ppr_projections!$A:$B,2,FALSE) -> 144.6 | AD37: =VLOOKUP(F37,[3]rotoballer_ppr_projections!$B:$G,6,FALSE) -> 210 | AE37: =VLOOKUP(F37,[4]ppr!$B:$E,4,FALSE) -> 229.93787 | AF37: =VLOOKUP(F37,[4]half_ppr!$B:$E,4,FALSE) -> 188.13099 | AG37: =VLOOKUP(F37,[4]std!$B:$E,4,FALSE) -> 146.3241 | AH37: =IFERROR(VLOOKUP(F37,[5]actual_week11_ppr_stats!$A:$B,2,FALSE),0) -> 152.8
A38: 37 | B38: 12729 | C38: Adams, Davante | D38: {=_xlfn.TEXTSPLIT(C38, ", ")} -> Adams | E38: Davante | F38: =_xlfn.REGEXREPLACE(E38 & " " & D38, "\.", "") -> Davante Adams | G38: LA | H38: WR | I38: 38.46 | J38: 18 | K38: 51 | L38: =VLOOKUP(G38,byes!$A:$B,2,FALSE) -> 8 | M38: =IF(L38=5,1,0) -> 0 | N38: =IF(L38=6,1,0) -> 0 | O38: =IF(L38=7,1,0) -> 0 | P38: =IF(L38=8,1,0) -> 1 | Q38: =IF(L38=9,1,0) -> 0 | R38: =IF(L38=10,1,0) -> 0 | S38: =IF(L38=11,1,0) -> 0 | T38: =IF(L38=12,1,0) -> 0 | U38: =IF(L38=14,1,0) -> 0 | V38: =IF(H38="QB", 1, 0) -> 0 | W38: =IF(H38="RB",1,0) -> 0 | X38: =IF(H38="WR",1,0) -> 1 | Y38: =IF(H38="TE",1,0) -> 0 | Z38: =IF(OR(H38="RB",H38="WR",H38="TE"),1,0) -> 1 | AA38: 1 | AB38: =VLOOKUP(F38,[1]pff_ppr_projections!$B:$D,3,FALSE) -> 225.2 | AC38: =VLOOKUP(F38,[2]numberFire_ppr_projections!$A:$B,2,FALSE) -> 226.8 | AD38: =VLOOKUP(F38,[3]rotoballer_ppr_projections!$B:$G,6,FALSE) -> 250 | AE38: =VLOOKUP(F38,[4]ppr!$B:$E,4,FALSE) -> 261.73059 | AF38: =VLOOKUP(F38,[4]half_ppr!$B:$E,4,FALSE) -> 214.99299 | AG38: =VLOOKUP(F38,[4]std!$B:$E,4,FALSE) -> 168.25538 | AH38: =IFERROR(VLOOKUP(F38,[5]actual_week11_ppr_stats!$A:$B,2,FALSE),0) -> 159.9
A39: 38 | B39: 17062 | C39: McLaurin, Terry | D39: {=_xlfn.TEXTSPLIT(C39, ", ")} -> McLaurin | E39: Terry | F39: =_xlfn.REGEXREPLACE(E39 & " " & D39, "\.", "") -> Terry McLaurin | G39: WAS | H39: WR | I39: 38.48 | J39: 27 | K39: 49 | L39: =VLOOKUP(G39,byes!$A:$B,2,FALSE) -> 12 | M39: =IF(L39=5,1,0) -> 0 | N39: =IF(L39=6,1,0) -> 0 | O39: =IF(L39=7,1,0) -> 0 | P39: =IF(L39=8,1,0) -> 0 | Q39: =IF(L39=9,1,0) -> 0 | R39: =IF(L39=10,1,0) -> 0 | S39: =IF(L39=11,1,0) -> 0 | T39: =IF(L39=12,1,0) -> 1 | U39: =IF(L39=14,1,0) -> 0 | V39: =IF(H39="QB", 1, 0) -> 0 | W39: =IF(H39="RB",1,0) -> 0 | X39: =IF(H39="WR",1,0) -> 1 | Y39: =IF(H39="TE",1,0) -> 0 | Z39: =IF(OR(H39="RB",H39="WR",H39="TE"),1,0) -> 1 | AA39: 1 | AB39: =VLOOKUP(F39,[1]pff_ppr_projections!$B:$D,3,FALSE) -> 235 | AC39: =VLOOKUP(F39,[2]numberFire_ppr_projections!$A:$B,2,FALSE) -> 253.9 | AD39: =VLOOKUP(F39,[3]rotoballer_ppr_projections!$B:$G,6,FALSE) -> 250 | AE39: =VLOOKUP(F39,[4]ppr!$B:$E,4,FALSE) -> 247.29141 | AF39: =VLOOKUP(F39,[4]half_ppr!$B:$E,4,FALSE) -> 205.14905 | AG39: =VLOOKUP(F39,[4]std!$B:$E,4,FALSE) -> 163.00668 | AH39: =IFERROR(VLOOKUP(F39,[5]actual_week11_ppr_stats!$A:$B,2,FALSE),0) -> 39.3
A40: 39 | B40: 12686 | C40: Evans, Mike | D40: {=_xlfn.TEXTSPLIT(C40, ", ")} -> Evans | E40: Mike | F40: =_xlfn.REGEXREPLACE(E40 & " " & D40, "\.", "") -> Mike Evans | G40: TB | H40: WR | I40: 38.74 | J40: 27 | K40: 51 | L40: =VLOOKUP(G40,byes!$A:$B,2,FALSE) -> 9 | M40: =IF(L40=5,1,0) -> 0 | N40: =IF(L40=6,1,0) -> 0 | O40: =IF(L40=7,1,0) -> 0 | P40: =IF(L40=8,1,0) -> 0 | Q40: =IF(L40=9,1,0) -> 1 | R40: =IF(L40=10,1,0) -> 0 | S40: =IF(L40=11,1,0) -> 0 | T40: =IF(L40=12,1,0) -> 0 | U40: =IF(L40=14,1,0) -> 0 | V40: =IF(H40="QB", 1, 0) -> 0 | W40: =IF(H40="RB",1,0) -> 0 | X40: =IF(H40="WR",1,0) -> 1 | Y40: =IF(H40="TE",1,0) -> 0 | Z40: =IF(OR(H40="RB",H40="WR",H40="TE"),1,0) -> 1 | AA40: 1 | AB40: =VLOOKUP(F40,[1]pff_ppr_projections!$B:$D,3,FALSE) -> 232.6 | AC40: =VLOOKUP(F40,[2]numberFire_ppr_projections!$A:$B,2,FALSE) -> 252.5 | AD40: =VLOOKUP(F40,[3]rotoballer_ppr_projections!$B:$G,6,FALSE) -> 251 | AE40: =VLOOKUP(F40,[4]ppr!$B:$E,4,FALSE) -> 245.72232 | AF40: =VLOOKUP(F40,[4]half_ppr!$B:$E,4,FALSE) -> 205.46637 | AG40: =VLOOKUP(F40,[4]std!$B:$E,4,FALSE) -> 165.21042 | AH40: =IFERROR(VLOOKUP(F40,[5]actual_week11_ppr_stats!$A:$B,2,FALSE),0) -> 34
...

Sheet byes
A1: Team | B1: Bye Week
A2: ATL | B2: 5
A3: CHI | B3: 5
A4: GB | B4: 5
A5: PIT | B5: 5
A6: HOU | B6: 6
A7: MIN | B7: 6
A8: BAL | B8: 7
A9: BUF | B9: 7
A10: ARZ | B10: 8
A11: DET | B11: 8
A12: JAX | B12: 8
A13: LV | B13: 8
... A33: SF | B33: 14
